Workbook

Sheet Monthly Savings
A1: Income Amounts(Monthly Not Including Savings) | C1: Notes
A2: 7550 | B2: Family USAA Checking #5494 | C2: Starting the month of August 2025 $1800 was put back here as we no longer pay for private schooling
A3: 300 | B3: Jamie USAA Checking #1986 | C3: Left over so Jamie does not have to go and change current bills being paid for
A4: 4179 | B4: Chime Prepaid Visa | C4: Bills paid with this Prepaid Card can be found on the monthly expenses sheet, added. This is over the amount you will see being calculated for cushion on bill that might fluctuate and unplanned cost.
A5: =SUM(A2:A4) -> 12029 | B5: Total Monthly Income For Checking
A7: Savings & Allowance Amount (Monthly)
A8: 300 | B8: Jamie USAA Checking #1986
A9: 200 | B9: Kevin NFCU checking allowance | C9: #7710
A10: 75 | B10: Kevin Greenwood Checking | C10: Traveling Fund, 4.15%APR Savings Account
A11: 0 | B11: Kevin NFCU Savings
A12: 100 | B12: Kevin Roth IRA
A13: 0 | B13: Jamie Roth IRA
A14: =SUM(A8:A13) -> 675 | B14: Total Month Savings
A16: =SUM(A5,A14) -> 12704 | B16: Income Plus Savings

Sheet Jamie 
A1: Bills | B1: Amount | C1: Frequency | D1: Balance
A2: Affirm | B2: 320 | C2: Monthly | D2: 1426.44
A3: Paypal Credit | B3: 175 | C3: 1st | D3: 5055.6
A4: Paypal Master card | B4: 52 | C4: 1st | D4: 1426.83
A5: Amex | B5: 40 | C5: 1st | D5: 1995.4
A6: Chuckie Cheese Monthly Pass | B6: 11.99 | C6: 15th
A7: Bestbuy | B7: 150 | C7: 15th | D7: 8000
A8: Life Insurance | B8: 86.51 | C8: 15th
A9: Navy Federal | B9: 254 | C9: 1st | D9: 20314.11
A10: Navy Federal | B10: 258 | C10: 15th | D10: 20568.34
A11: Old Navy | B11: 40 | C11: 1st | D11: 1100
A12: USAA | B12: 150 | D12: 6059.46
B14: $2192.81 bi weekly pay | D14: $4385.62 monthly

Sheet Monthly Expenses 
A1: ='Monthly Savings'!A5 -> 12029 | B1: Monthly Income (After Savings)
B2: *All Are High Estimates
A3: Expense Amounts | B3: Expense | C3: Additional Notes | D3: Paid with Chime Prepaid Visa?
A4: 270 | B4: Electric Bill | C4: Average Cost, Utility, Paid on the 21st Using SmartHub App | D4: Paid with Chime Prepaid Visa
A5: 86.51 | B5: Life Insurance (Jamie)
A6: 92 | B6: Term Life Insurance (Kevin)
A7: 11 | B7: Tidal
A8: 20 | B8: Netflix | D8: Paid with Chime Prepaid Visa
A9: 1820 | B9: Rent | D9: Paid with Chime Prepaid Visa
A10: 145 | B10: Verizon Wireless Plus Streaming Services | C10: Includes Hulu, Disney+, Espn+ Subscription | D10: Paid with Chime Prepaid Visa
A11: 46 | B11: EnviroGuard Pest Control | C11: $90 paid every 2 months | D11: Paid with Chime Prepaid Visa
A12: 50 | B12: Lawn and Garden
A13: 85 | B13: AT&T | D13: Paid with Chime Prepaid Visa
A14: 5 | B14: Ring | D14: Paid with Chime Prepaid Visa
A15: 12 | B15: ExpressVPN
A16: 16 | B16: Amazon Prime
A17: 10 | B17: Notion (Note Taking Application) | D17: Paid with Chime Prepaid Visa
A18: 5 | B18: Privacy.com - Plus Subscription | C18: for security of online purchasing using
A19: 250 | B19: Car + Renter's Insurance
A20: 250 | B20: Hair Appointments/Hair Products
A21: 100 | B21: Skin care products
A22: 140 | B22: Nail Salon
A23: 400 | B23: Clothing Items | C23: Kids and Adults
A24: 0 | B24: Student Loans (Jamie) | C24: Paused
A25: 137 | B25: Student Loans (Kevin) | D25: Paid with Chime Prepaid Visa
A26: 100 | B26: Sewage/Trash/Water - Utilties | C26: Average Cost (City of Selma) | D26: Paid with Chime Prepaid Visa
A27: 600 | B27: Groceries | C27: Average Cost
A28: 1000 | B28: Eating out/entertainment | C28: Average Cost
A29: 100 | B29: Household Items | C29: Average Cost
A30: 100 | B30: Toiletries | C30: Average Cost
A31: 30 | B31: Quip Toothbrush Subscription | C31: $89 every 3 months for 2x Original Standard Soft-Bristle Brush Head 1x Floss String Refill Spool 1x Large Mint Anticavity Toothpaste 1x 90-Piece Gum Refill (9 Packs) 2x Original Small Soft-Bristle Brush Head 1x Large Watermelon Anticavity Toothpaste 1x Floss Pick Refill Pod - Expanding String | D31: Paid with Chime Prepaid Visa
A32: 350 | B32: Vehicle Gas | C32: Average Cost
A33: 7 | B33: New York Times, The Daily | D33: Paid with Chime Prepaid Visa
A34: 21 | B34: Cheroenhaka Tribal Foundation | C34: www.nfggive.org - Network For Good
A35: 50 | B35: Revelation Church SA
A36: 3.33 | B36: BitWarden | C36: Paid on a yearly basis at $10/year
A37: 10 | B37: SiriusXM | C37: $127/year paid at once
A38: 2 | B38: Chris Flick Comics
A39: 2 | B39: World Central Kitchen
A40: 0 | B40: Believer's Academy | C40: monthly tuition plus any other school-related expenses | D40: Paid with Chime Prepaid Visa
...

Sheet Debt Owed Breakdown
A1: Debt Owed | B1: Current Balance | C1: Date Recorded | D1: Notes
A2: Paypal Pay Later - Kevin | B2: 0 | C2: 46043.835 | D2: Pay Later
A3: Barclays - Kevin | B3: 0 | C3: 45199.533 | D3: Credit Card
A4: NFCU Visa - Kevin | B4: 0 | C4: 45963.069 | D4: Credit Card
A5: Klarna Payments - Kevin | B5: 382.4 | C5: 46043.83 | D5: Pay Later
A6: Barclays - Jamie | B6: 1114.16 | C6: 46013.719 | D6: Credit Card
A7: Affirm Payments - Jamie | B7: 1672 | C7: 46013.73 | D7: Pay Later
A8: Mastercard-Jamie | B8: 1433.87 | C8: 46013.722 | D8: Credit Card
A9: AMEX-Jamie | B9: 2047.89 | C9: 46013.722 | D9: Credit Card
A10: Affirm Payments - Kevin | B10: 3297.44 | C10: 46043.832 | D10: Pay Later
A11: USAA Visa - Kevin | B11: 5042.75 | C11: 46043.83 | D11: Credit Card
A12: Paypal Credit-Jamie | B12: 4987.88 | C12: 46013.722 | D12: Credit
A13: USAA VISA - Jamie | B13: 6073.1 | C13: 46013.722 | D13: Credit Card
... A18: USAA Amex - Kevin | B18: 21401.48 | C18: 46043.831 | D18: Credit Card
A19: Total
A20: =DOLLAR(SUM(B2:B18)) -> $108,973.46

Sheet Monthly Debt Owed Payments
A1: ='Monthly Expenses '!A55 -> 4832.16 | B1: Total Amount After Expenses Paid & Estimated Expense Allocation | C1: Notes | D1: Debt Amount | E1: Date Recorded | F1: Monthly Balance Change
D2: =DOLLAR(24213.12) -> $24,213.12 | E2: 43135.989
B3: Credit Cards | D3: =DOLLAR(24354.22) -> $24,354.22 | E3: 43163.891 | F3: =DOLLAR(D3-D2) -> $141.10
A4: 600 | B4: USAA Amex | D4: =DOLLAR(27399.76) -> $27,399.76 | E4: 43200.504 | F4: =DOLLAR(D4-D3) -> $3,045.54
A5: 0 | B5: Kevin Barclays Visa | C5: PAID OFF!!!!!! | D5: =DOLLAR(28381.08) -> $28,381.08 | E5: 43228.587 | F5: =DOLLAR(D5-D4) -> $981.32
A6: 260 | B6: Jamie NFCU Visa - 0454 | D6: =DOLLAR(28833.06) -> $28,833.06 | E6: 43257.436 | F6: =DOLLAR(D6-D5) -> $451.98
A7: 258 | B7: Jamie NFCU Visa-5392 | D7: =DOLLAR(31188.23) -> $31,188.23 | E7: 43292.922 | F7: =DOLLAR(D7-D6) -> $2,355.17
A8: 0 | B8: Kevin NFCU Visa | C8: PAID OFF!!!!!! | D8: =DOLLAR(5912.46) -> $5,912.46
A9: 150 | B9: Jamie USAA Visa | D9: =DOLLAR(1956.4) -> $1,956.40
A10: 40 | B10: Jamie AMEX | D10: =DOLLAR(1374.83) -> $1,374.83
A11: 150 | B11: Jamie Best Buy | D11: =DOLLAR(36910.39) -> $36,910.39 | E11: 43331.861 | F11: =DOLLAR(D11-D7) -> $5,722.16
A12: 175 | B12: Jamie Pay Pal Credit | D12: =DOLLAR(43868.12) -> $43,868.12 | E12: 43436.022 | F12: =DOLLAR(D12-D11) -> $6,957.73
A13: 52 | B13: Jamie Mastercard | D13: =DOLLAR(45166.2) -> $45,166.20 | E13: 43469.588 | F13: =DOLLAR(D13-D12) -> $1,298.08
A14: 190 | B14: Jamie Barclays Visa (Old Navy) | D14: =DOLLAR(49162.25) -> $49,162.25 | E14: 43512.5 | F14: =DOLLAR(D14-D13) -> $3,996.05
A15: 95 | B15: Kevin Klarma | D15: =DOLLAR(45440.82) -> $45,440.82 | E15: 43534.531 | F15: =DOLLAR(D15-D14) -> -$3,721.43
A16: 280 | B16: Kevin Affirm | D16: =DOLLAR(37075.56) -> $37,075.56 | E16: 43564.569 | F16: =DOLLAR(D16-D15) -> -$8,365.26
A17: 0 | B17: Kevin PayPal | C17: PAID OFF!!! | D17: =DOLLAR(36057.53) -> $36,057.53 | E17: 43594.433 | F17: =DOLLAR(D17-D16) -> -$1,018.03
A18: 200 | B18: Kevin USAA Visa | D18: =DOLLAR(34955.56) -> $34,955.56 | E18: 43624.98 | F18: =DOLLAR(D18-D17) -> -$1,101.97
A19: =SUM(A4:A18) -> 2450 | B19: Total Amount in Debt Owed Payments | D19: =DOLLAR(35822.32) -> $35,822.32 | E19: 43654.557 | F19: =DOLLAR(D19-D18) -> $866.76
D20: =DOLLAR(36059.74) -> $36,059.74 | E20: 43686.482 | F20: =DOLLAR(D20-D19) -> $237.42
A21: =MINUS(A1,A19) -> 2382.16 | B21: Cash After Debt Owed Payments | D21: =DOLLAR(38522.86) -> $38,522.86 | E21: 43720.413 | F21: =DOLLAR(D21-D20) -> $2,463.12
D22: =DOLLAR(40096.72) -> $40,096.72 | E22: 43748.514 | F22: =DOLLAR(D22-D21) -> $1,573.86
D23: =DOLLAR(42630.42) -> $42,630.42 | E23: 43778.901 | F23: =DOLLAR(D23-D22) -> $2,533.70
D24: =DOLLAR(43863.81) -> $43,863.81 | E24: 43809.867 | F24: =DOLLAR(D24-D23) -> $1,233.39
D25: =DOLLAR(45619.52) -> $45,619.52 | E25: 43852.417 | F25: =DOLLAR(D25-D24) -> $1,755.71
D26: =DOLLAR(57581.36) -> $57,581.36 | E26: 44189.466 | F26: =DOLLAR(D26-D25) -> $11,961.84
D27: =DOLLAR(57000) -> $57,000.00 | E27: 44547.428 | F27: =DOLLAR(D27-D26) -> -$581.36
D28: =Dollar(51000) -> $51,000.00 | E28: 44642 | F28: =DOLLAR(D28-D27) -> -$6,000.00
D29: =DOLLAR(52687.37) -> $52,687.37 | E29: 44734 | F29: =DOLLAR(D29-D28) -> $1,687.37
D30: =DOLLAR(39918.53) -> $39,918.53 | E30: 44866 | F30: =DOLLAR(D30-D29) -> -$12,768.84
D31: =DOLLAR(36610.74) -> $36,610.74 | E31: 44897 | F31: =DOLLAR(D31-D30) -> -$3,307.79
D32: =DOLLAR(34248.3) -> $34,248.30 | E32: 44954 | F32: =DOLLAR(D32-D31) -> -$2,362.44
D33: =DOLLAR(33391.55) -> $33,391.55 | E33: 45014 | F33: =DOLLAR(D33-D32) -> -$856.75
D34: =DOLLAR(35453.77) -> $35,453.77 | E34: 45054 | F34: =DOLLAR(D34-D33) -> $2,062.22
D35: =DOLLAR(35677.16) -> $35,677.16 | E35: 45140 | F35: =DOLLAR(D35-D34) -> $223.39
D36: =DOLLAR(32922.34) -> $32,922.34 | E36: 45170 | F36: =DOLLAR(D36-D35) -> -$2,754.82
D37: =DOLLAR(31149.17) -> $31,149.17 | E37: 45200 | F37: =DOLLAR(D37-D36) -> -$1,773.17
D38: =DOLLAR(31647.43) -> $31,647.43 | E38: 45254 | F38: =DOLLAR(D38-D37) -> $498.26
D39: =DOLLAR(28759.84) -> $28,759.84 | E39: 45455 | F39: =DOLLAR(D39-D38) -> -$2,887.59
D40: =DOLLAR(44318.32) -> $44,318.32 | E40: 45694 | F40: =DOLLAR(D40-D39) -> $15,558.48
...

Sheet Medical Bills
A1: Bill Name | B1: Total Amount | C1: Amount Remaining | D1: Monthly Payments | E1: HSA Payment Day | F1: Additonal Notes
A2: Diversified Healthcare Services | C2: 888.37 | D2: 50 | E2: 5th | F2: Ref 10154184
A3: Aspira | B3: 295 | C3: 295 | F3: Acct#A0155419/866-927-7472
A4: Virtusa GYN | B4: 987.89 | C4: 576.29 | D4: 82.32 | E4: last business day of month | F4: 210-878-0090
A5: Genova Diagnostics | B5: 289 | C5: 289
A6: Methodist Hospital Northeast | B6: 919.3 | C6: 804.38 | D6: 114.92 | E6: 23rd of each month | F6: Medicredi 800-823-2318 ref: 194975821
A7: Northeast medical facilty | B7: 307.17 | C7: 204.78 | D7: 102.39 | F7: 1-844-974-3800 Acct: 467354305
B8: Total Medical Debt | C8: Total Remaining Debt | D8: Total Monthly Payments
B9: =SUM(B1:B7) -> 2798.36 | C9: =SUM(C1:C2) -> 888.37 | D9: =SUM(D1:D7) -> 349.63

Sheet HSA Paybacks
A1: Amount | B1: For What? | C1: Year | D1: Paid? | E1: Total Payout | F1: Total Payout Remaining
A2: 30 | B2: Abcd Pediatrics | C2: 2022 | D2: TRUE
A3: 191.97 | B3: To Jamie for Total Healthcare Payment | C3: 2021 | D3: TRUE
A4: 89.61 | B4: Methodist physicians (Jamie) | C4: 2021 | D4: FALSE | E4: =SUM(A:A) -> 10164.85 | F4: =SUMIF(D:D,"=FALSE",A:A) -> 8889.52
A5: 107.48 | B5: peds doc bill | C5: 2021 | D5: FALSE
A6: 240 | B6: co pays for kids doc visits | C6: 2021 | D6: FALSE
A7: 18 | B7: Trojan condoms | C7: 2021 | D7: TRUE
A8: 60 | B8: Texas Pediatrics - Sleep consultation copay | C8: 2021 | D8: TRUE
A9: 35.57 | B9: CVS for Emma and KJ | C9: 2021 | D9: TRUE
A10: 45.4 | B10: Emma's medication | C10: 2021 | D10: TRUE
A11: 350 | B11: Physical visit with Integrative | C11: 2021 | D11: FALSE
A12: 34 | B12: Supergoop Sunscreen | C12: 2022 | D12: FALSE
A13: 39 | B13: Gottman questionnaire | C13: 2022 | D13: FALSE
A14: 60 | B14: Dermatologist Copay | C14: 2022 | D14: FALSE
A15: 63.21 | B15: final payment Dr. Albricht | C15: 2022 | D15: FALSE
A16: 120 | B16: kids allergist co pay | C16: 2022 | D16: FALSE
... A88: 73 | B88: LMNT Electrolyte drinks | C88: 2025 | D88: FALSE
A89: 17 | C89: 2025 | D89: FALSE
A90: 150 | B90: Hill Country Endodontics (dentistry) | C90: 2025 | D90: FALSE
A91: 49 | B91: Vision source-Jamie eye exam | C91: 2025 | D91: FALSE
A92: 344.84 | B92: Full script-Jamie vitamins | C92: 2025 | D92: FALSE
A93: 50 | B93: Ralph Demur (Kevin Individual Counseling) | C93: 2025 | D93: FALSE
A94: 50 | B94: Ralph Demur (Kevin Individual Counseling) | C94: 2025 | D94: FALSE
A95: 50 | B95: Ralph Demur (Kevin Individual Counseling) | C95: 2025 | D95: FALSE
A96: 175 | B96: Physical visit with Integrative Family Medicine | C96: 2025 | D96: FALSE
A97: 50 | B97: Ralph Demur (Kevin Individual Counseling) | C97: 2025 | D97: FALSE
A98: 285 | B98: Visit with Integrative Family Medicine (Jamie, $100 already withdrawn from HSA as total was $385) | C98: 2025 | D98: FALSE
A99: 50 | B99: Ralph Demur (Kevin Individual Counseling) | C99: 2025 | D99: FALSE
A100: 50 | B100: Ralph Demur (Kevin Individual Counseling) | C100: 2025 | D100: FALSE
A101: 75 | B101: Ralph Demur (Kevin Individual Counseling) | C101: 2026 | D101: FALSE

Sheet Current Networth
A1: What we Own (Assets) | B1: Amount | C1: What we Owe (Debts) | D1: Amount | E1: Notes | F1: Networth
A2: Cash (Estimate of All Savings) | B2: 1500 | C2: Credit Card/Pay For Later | D2: ='Debt Owed Breakdown'!A20*-1 -> -108973.46 | F2: =SUM(B14+D13) -> -13867.28
A3: Car - SC | B3: 14000 | C3: Student Loan Debt SC | D3: -149320
A4: Car - HB | B4: 4000 | C4: Student Loan Debt HB | D4: -9498.91
A5: Roth IRA - SC | B5: 1116.32 | C5: Medical Debt | D5: ='Medical Bills'!C9*-1 -> -888.37
A6: Roth IRA - HB | B6: 51800 | C6: NFCU Auto Loan | D6: ='Debt Owed Breakdown'!B15*-1 -> -15512.01
A7: Traditional IRA - SC | B7: 2649.73
A8: Traditional IRA - HB | B8: 123201
A9: Booz Allen Hamilton 401k- HB | B9: 63374.42
A10: 401K - SC
A11: College Savings 529 | B11: 5784
A12: Stocks/Crypto/BlockChain | B12: 400
A13: State of MD Retirement | B13: 2500 | C13: Total | D13: =SUM(D2:D12) -> -284192.75
A14: Total | B14: =SUM(B2:B13) -> 270325.47
